Sat, 06 Aug 2022 12:40:32-app-app.py-[line:1449]-ERROR-[日志信息]: Exception on /api/login [POST]
Traceback (most recent call last):
  File "D:\Programs\Python\Python310\lib\site-packages\flask\app.py", line 2073, in wsgi_app
    response = self.full_dispatch_request()
  File "D:\Programs\Python\Python310\lib\site-packages\flask\app.py", line 1519, in full_dispatch_request
    rv = self.handle_user_exception(e)
  File "D:\Programs\Python\Python310\lib\site-packages\flask\app.py", line 1517, in full_dispatch_request
    rv = self.dispatch_request()
  File "D:\Programs\Python\Python310\lib\site-packages\flask\app.py", line 1503, in dispatch_request
    return self.ensure_sync(self.view_functions[rule.endpoint])(**req.view_args)
  File "D:\git-python\userservive\userservice\views\auth.py", line 40, in login
    return jsonify(response)
  File "D:\Programs\Python\Python310\lib\site-packages\flask\json\__init__.py", line 302, in jsonify
    f"{dumps(data, indent=indent, separators=separators)}\n",
  File "D:\Programs\Python\Python310\lib\site-packages\flask\json\__init__.py", line 132, in dumps
    return _json.dumps(obj, **kwargs)
  File "D:\Programs\Python\Python310\lib\json\__init__.py", line 238, in dumps
    **kw).encode(obj)
  File "D:\Programs\Python\Python310\lib\json\encoder.py", line 199, in encode
    chunks = self.iterencode(o, _one_shot=True)
  File "D:\Programs\Python\Python310\lib\json\encoder.py", line 257, in iterencode
    return _iterencode(o, 0)
  File "D:\Programs\Python\Python310\lib\site-packages\flask\json\__init__.py", line 51, in default
    return super().default(o)
  File "D:\Programs\Python\Python310\lib\json\encoder.py", line 179, in default
    raise TypeError(f'Object of type {o.__class__.__name__} '
TypeError: Object of type ResCode is not JSON serializable
Sat, 06 Aug 2022 12:40:32-app-app.py-[line:1449]-ERROR-[日志信息]: Exception on /api/login [POST]
Traceback (most recent call last):
  File "D:\Programs\Python\Python310\lib\site-packages\flask\app.py", line 2073, in wsgi_app
    response = self.full_dispatch_request()
  File "D:\Programs\Python\Python310\lib\site-packages\flask\app.py", line 1519, in full_dispatch_request
    rv = self.handle_user_exception(e)
  File "D:\Programs\Python\Python310\lib\site-packages\flask\app.py", line 1517, in full_dispatch_request
    rv = self.dispatch_request()
  File "D:\Programs\Python\Python310\lib\site-packages\flask\app.py", line 1503, in dispatch_request
    return self.ensure_sync(self.view_functions[rule.endpoint])(**req.view_args)
  File "D:\git-python\userservive\userservice\views\auth.py", line 40, in login
    return jsonify(response)
  File "D:\Programs\Python\Python310\lib\site-packages\flask\json\__init__.py", line 302, in jsonify
    f"{dumps(data, indent=indent, separators=separators)}\n",
  File "D:\Programs\Python\Python310\lib\site-packages\flask\json\__init__.py", line 132, in dumps
    return _json.dumps(obj, **kwargs)
  File "D:\Programs\Python\Python310\lib\json\__init__.py", line 238, in dumps
    **kw).encode(obj)
  File "D:\Programs\Python\Python310\lib\json\encoder.py", line 199, in encode
    chunks = self.iterencode(o, _one_shot=True)
  File "D:\Programs\Python\Python310\lib\json\encoder.py", line 257, in iterencode
    return _iterencode(o, 0)
  File "D:\Programs\Python\Python310\lib\site-packages\flask\json\__init__.py", line 51, in default
    return super().default(o)
  File "D:\Programs\Python\Python310\lib\json\encoder.py", line 179, in default
    raise TypeError(f'Object of type {o.__class__.__name__} '
TypeError: Object of type ResCode is not JSON serializable
Sat, 06 Aug 2022 12:40:32-app-app.py-[line:1449]-ERROR-[日志信息]: Exception on /api/login [POST]
Traceback (most recent call last):
  File "D:\Programs\Python\Python310\lib\site-packages\flask\app.py", line 2073, in wsgi_app
    response = self.full_dispatch_request()
  File "D:\Programs\Python\Python310\lib\site-packages\flask\app.py", line 1519, in full_dispatch_request
    rv = self.handle_user_exception(e)
  File "D:\Programs\Python\Python310\lib\site-packages\flask\app.py", line 1517, in full_dispatch_request
    rv = self.dispatch_request()
  File "D:\Programs\Python\Python310\lib\site-packages\flask\app.py", line 1503, in dispatch_request
    return self.ensure_sync(self.view_functions[rule.endpoint])(**req.view_args)
  File "D:\git-python\userservive\userservice\views\auth.py", line 40, in login
    return jsonify(response)
  File "D:\Programs\Python\Python310\lib\site-packages\flask\json\__init__.py", line 302, in jsonify
    f"{dumps(data, indent=indent, separators=separators)}\n",
  File "D:\Programs\Python\Python310\lib\site-packages\flask\json\__init__.py", line 132, in dumps
    return _json.dumps(obj, **kwargs)
  File "D:\Programs\Python\Python310\lib\json\__init__.py", line 238, in dumps
    **kw).encode(obj)
  File "D:\Programs\Python\Python310\lib\json\encoder.py", line 199, in encode
    chunks = self.iterencode(o, _one_shot=True)
  File "D:\Programs\Python\Python310\lib\json\encoder.py", line 257, in iterencode
    return _iterencode(o, 0)
  File "D:\Programs\Python\Python310\lib\site-packages\flask\json\__init__.py", line 51, in default
    return super().default(o)
  File "D:\Programs\Python\Python310\lib\json\encoder.py", line 179, in default
    raise TypeError(f'Object of type {o.__class__.__name__} '
TypeError: Object of type ResCode is not JSON serializable
Sat, 06 Aug 2022 12:40:32-app-app.py-[line:1449]-ERROR-[日志信息]: Exception on /api/login [POST]
Traceback (most recent call last):
  File "D:\Programs\Python\Python310\lib\site-packages\flask\app.py", line 2073, in wsgi_app
    response = self.full_dispatch_request()
  File "D:\Programs\Python\Python310\lib\site-packages\flask\app.py", line 1519, in full_dispatch_request
    rv = self.handle_user_exception(e)
  File "D:\Programs\Python\Python310\lib\site-packages\flask\app.py", line 1517, in full_dispatch_request
    rv = self.dispatch_request()
  File "D:\Programs\Python\Python310\lib\site-packages\flask\app.py", line 1503, in dispatch_request
    return self.ensure_sync(self.view_functions[rule.endpoint])(**req.view_args)
  File "D:\git-python\userservive\userservice\views\auth.py", line 40, in login
    return jsonify(response)
  File "D:\Programs\Python\Python310\lib\site-packages\flask\json\__init__.py", line 302, in jsonify
    f"{dumps(data, indent=indent, separators=separators)}\n",
  File "D:\Programs\Python\Python310\lib\site-packages\flask\json\__init__.py", line 132, in dumps
    return _json.dumps(obj, **kwargs)
  File "D:\Programs\Python\Python310\lib\json\__init__.py", line 238, in dumps
    **kw).encode(obj)
  File "D:\Programs\Python\Python310\lib\json\encoder.py", line 199, in encode
    chunks = self.iterencode(o, _one_shot=True)
  File "D:\Programs\Python\Python310\lib\json\encoder.py", line 257, in iterencode
    return _iterencode(o, 0)
  File "D:\Programs\Python\Python310\lib\site-packages\flask\json\__init__.py", line 51, in default
    return super().default(o)
  File "D:\Programs\Python\Python310\lib\json\encoder.py", line 179, in default
    raise TypeError(f'Object of type {o.__class__.__name__} '
TypeError: Object of type ResCode is not JSON serializable
Sat, 06 Aug 2022 12:40:32-app-app.py-[line:1449]-ERROR-[日志信息]: Exception on /api/login [POST]
Traceback (most recent call last):
  File "D:\Programs\Python\Python310\lib\site-packages\flask\app.py", line 2073, in wsgi_app
    response = self.full_dispatch_request()
  File "D:\Programs\Python\Python310\lib\site-packages\flask\app.py", line 1519, in full_dispatch_request
    rv = self.handle_user_exception(e)
  File "D:\Programs\Python\Python310\lib\site-packages\flask\app.py", line 1517, in full_dispatch_request
    rv = self.dispatch_request()
  File "D:\Programs\Python\Python310\lib\site-packages\flask\app.py", line 1503, in dispatch_request
    return self.ensure_sync(self.view_functions[rule.endpoint])(**req.view_args)
  File "D:\git-python\userservive\userservice\views\auth.py", line 40, in login
    return jsonify(response)
  File "D:\Programs\Python\Python310\lib\site-packages\flask\json\__init__.py", line 302, in jsonify
    f"{dumps(data, indent=indent, separators=separators)}\n",
  File "D:\Programs\Python\Python310\lib\site-packages\flask\json\__init__.py", line 132, in dumps
    return _json.dumps(obj, **kwargs)
  File "D:\Programs\Python\Python310\lib\json\__init__.py", line 238, in dumps
    **kw).encode(obj)
  File "D:\Programs\Python\Python310\lib\json\encoder.py", line 199, in encode
    chunks = self.iterencode(o, _one_shot=True)
  File "D:\Programs\Python\Python310\lib\json\encoder.py", line 257, in iterencode
    return _iterencode(o, 0)
  File "D:\Programs\Python\Python310\lib\site-packages\flask\json\__init__.py", line 51, in default
    return super().default(o)
  File "D:\Programs\Python\Python310\lib\json\encoder.py", line 179, in default
    raise TypeError(f'Object of type {o.__class__.__name__} '
TypeError: Object of type ResCode is not JSON serializable
Sat, 06 Aug 2022 12:40:32-app-app.py-[line:1449]-ERROR-[日志信息]: Exception on /api/login [POST]
Traceback (most recent call last):
  File "D:\Programs\Python\Python310\lib\site-packages\flask\app.py", line 2073, in wsgi_app
    response = self.full_dispatch_request()
  File "D:\Programs\Python\Python310\lib\site-packages\flask\app.py", line 1519, in full_dispatch_request
    rv = self.handle_user_exception(e)
  File "D:\Programs\Python\Python310\lib\site-packages\flask\app.py", line 1517, in full_dispatch_request
    rv = self.dispatch_request()
  File "D:\Programs\Python\Python310\lib\site-packages\flask\app.py", line 1503, in dispatch_request
    return self.ensure_sync(self.view_functions[rule.endpoint])(**req.view_args)
  File "D:\git-python\userservive\userservice\views\auth.py", line 40, in login
    return jsonify(response)
  File "D:\Programs\Python\Python310\lib\site-packages\flask\json\__init__.py", line 302, in jsonify
    f"{dumps(data, indent=indent, separators=separators)}\n",
  File "D:\Programs\Python\Python310\lib\site-packages\flask\json\__init__.py", line 132, in dumps
    return _json.dumps(obj, **kwargs)
  File "D:\Programs\Python\Python310\lib\json\__init__.py", line 238, in dumps
    **kw).encode(obj)
  File "D:\Programs\Python\Python310\lib\json\encoder.py", line 199, in encode
    chunks = self.iterencode(o, _one_shot=True)
  File "D:\Programs\Python\Python310\lib\json\encoder.py", line 257, in iterencode
    return _iterencode(o, 0)
  File "D:\Programs\Python\Python310\lib\site-packages\flask\json\__init__.py", line 51, in default
    return super().default(o)
  File "D:\Programs\Python\Python310\lib\json\encoder.py", line 179, in default
    raise TypeError(f'Object of type {o.__class__.__name__} '
TypeError: Object of type ResCode is not JSON serializable
Sat, 06 Aug 2022 13:05:56-root-auth.py-[line:80]-ERROR-[日志信息]: '>' not supported between instances of 'NoneType' and 'int'
Sat, 06 Aug 2022 13:05:56-root-auth.py-[line:80]-ERROR-[日志信息]: '>' not supported between instances of 'NoneType' and 'int'
Sat, 06 Aug 2022 13:05:56-root-auth.py-[line:80]-ERROR-[日志信息]: '>' not supported between instances of 'str' and 'int'
Sat, 06 Aug 2022 13:05:56-root-auth.py-[line:80]-ERROR-[日志信息]: '>' not supported between instances of 'str' and 'int'
Sat, 06 Aug 2022 13:05:56-root-auth.py-[line:80]-ERROR-[日志信息]: '>' not supported between instances of 'str' and 'int'
Sat, 06 Aug 2022 13:05:56-root-auth.py-[line:80]-ERROR-[日志信息]: '>' not supported between instances of 'str' and 'int'
Sat, 06 Aug 2022 13:05:56-root-auth.py-[line:80]-ERROR-[日志信息]: '>' not supported between instances of 'str' and 'int'
Sat, 06 Aug 2022 13:05:56-root-auth.py-[line:80]-ERROR-[日志信息]: '>' not supported between instances of 'str' and 'int'
Sat, 06 Aug 2022 13:05:57-root-auth.py-[line:80]-ERROR-[日志信息]: '>' not supported between instances of 'str' and 'int'
Sat, 06 Aug 2022 13:05:57-root-auth.py-[line:80]-ERROR-[日志信息]: '>' not supported between instances of 'str' and 'int'
Sat, 06 Aug 2022 13:05:57-root-auth.py-[line:80]-ERROR-[日志信息]: '>' not supported between instances of 'str' and 'int'
Sat, 06 Aug 2022 13:05:57-root-auth.py-[line:80]-ERROR-[日志信息]: '>' not supported between instances of 'str' and 'int'
Sat, 06 Aug 2022 13:05:57-root-auth.py-[line:80]-ERROR-[日志信息]: '>' not supported between instances of 'str' and 'int'
Sat, 06 Aug 2022 13:05:57-root-auth.py-[line:80]-ERROR-[日志信息]: '>' not supported between instances of 'str' and 'int'
Sat, 06 Aug 2022 13:06:27-root-auth.py-[line:80]-ERROR-[日志信息]: '>' not supported between instances of 'NoneType' and 'int'
Sat, 06 Aug 2022 13:06:27-root-auth.py-[line:80]-ERROR-[日志信息]: '>' not supported between instances of 'NoneType' and 'int'
Sat, 06 Aug 2022 13:06:27-root-auth.py-[line:80]-ERROR-[日志信息]: '>' not supported between instances of 'str' and 'int'
Sat, 06 Aug 2022 13:06:27-root-auth.py-[line:80]-ERROR-[日志信息]: '>' not supported between instances of 'str' and 'int'
Sat, 06 Aug 2022 13:06:27-root-auth.py-[line:80]-ERROR-[日志信息]: '>' not supported between instances of 'str' and 'int'
Sat, 06 Aug 2022 13:06:27-root-auth.py-[line:80]-ERROR-[日志信息]: '>' not supported between instances of 'str' and 'int'
Sat, 06 Aug 2022 13:06:27-root-auth.py-[line:80]-ERROR-[日志信息]: '>' not supported between instances of 'str' and 'int'
Sat, 06 Aug 2022 13:06:27-root-auth.py-[line:80]-ERROR-[日志信息]: '>' not supported between instances of 'str' and 'int'
Sat, 06 Aug 2022 13:06:27-root-auth.py-[line:80]-ERROR-[日志信息]: '>' not supported between instances of 'str' and 'int'
Sat, 06 Aug 2022 13:06:27-root-auth.py-[line:80]-ERROR-[日志信息]: '>' not supported between instances of 'str' and 'int'
Sat, 06 Aug 2022 13:06:27-root-auth.py-[line:80]-ERROR-[日志信息]: '>' not supported between instances of 'str' and 'int'
Sat, 06 Aug 2022 13:06:27-root-auth.py-[line:80]-ERROR-[日志信息]: '>' not supported between instances of 'str' and 'int'
Sat, 06 Aug 2022 13:06:27-root-auth.py-[line:80]-ERROR-[日志信息]: '>' not supported between instances of 'str' and 'int'
Sat, 06 Aug 2022 13:06:27-root-auth.py-[line:80]-ERROR-[日志信息]: '>' not supported between instances of 'str' and 'int'
Sat, 06 Aug 2022 13:07:32-root-auth.py-[line:80]-ERROR-[日志信息]: '>' not supported between instances of 'NoneType' and 'int'
Sat, 06 Aug 2022 13:07:32-root-auth.py-[line:80]-ERROR-[日志信息]: '>' not supported between instances of 'NoneType' and 'int'
Sat, 06 Aug 2022 13:08:21-root-auth.py-[line:81]-ERROR-[日志信息]: int() argument must be a string, a bytes-like object or a real number, not 'NoneType'
Sat, 06 Aug 2022 13:08:21-root-auth.py-[line:81]-ERROR-[日志信息]: int() argument must be a string, a bytes-like object or a real number, not 'NoneType'
